Workbook

Sheet 红宝书去重版
A1: 顺序 | B1: 乱序 | C1: 假名 | D1: 汉字/外文 | E1: 形 | G1: 副 | H1: 叠 | I1: 特 | J1: 图源 | N1: 音源 | S1: 1遍 | T1: 2遍 | U1: 3遍 | V1: 正确率 | W1: 已学习 | Y1: 特殊备注 | Z1: 总进度 | AA1: N5进度 | AB1: N4进度 | AC1: N3进度 | AD1: N2进度 | AE1: N1进度
C2: 9574 | Z2: =COUNTA($W$3:$W$9575)/9574 -> 0 | AA2: =COUNTIFS($W$3:$W$9575,"<>",$X$3:$X$9575,"N5")/1000 -> 0 | AB2: =COUNTIFS($W$3:$W$9575,"<>",$X$3:$X$9575,"N4")/1121 -> 0 | AC2: =COUNTIFS($W$3:$W$9575,"<>",$X$3:$X$9575,"N3")/2072 -> 0 | AD2: =COUNTIFS($W$3:$W$9575,"<>",$X$3:$X$9575,"N2")/2328 -> 0 | AE2: =COUNTIFS($W$3:$W$9575,"<>",$X$3:$X$9575,"N1")/3053 -> 0
A3: 1 | B3: =RAND() -> 0.33361135 | C3: ああ | J3: =HYPERLINK(K3,"➸") -> ➸ | K3: =词典存放目录!$A$1&L3&M3 -> F:\《自创文法查阅Excel》4.1备份\《B词汇·红宝书》\红宝书15版图片\1-ああ.jpg | L3: \红宝书15版图片\ | M3: 1-ああ.jpg | N3: =HYPERLINK(R3,"▶") -> ▶ | O3: \红宝书MP3分割\01 n5-あ ( | P3: 1 | Q3: ).mp3 | R3: =词典存放目录!$A$1&O3&P3&Q3 -> F:\《自创文法查阅Excel》4.1备份\《B词汇·红宝书》\红宝书MP3分割\01 n5-あ (1).mp3 | V3: =IF(COUNTA(S3:U3)=0,"",COUNTIF(S3:U3,"0")/COUNTA(S3:U3)) | X3: N5 | Z3: =Z2 -> 0 | AA3: =AA2 -> 0 | AB3: =AB2 -> 0 | AC3: =AC2 -> 0 | AD3: =AD2 -> 0 | AE3: =AE2 -> 0
A4: 2 | B4: =RAND() -> 0.054255805 | C4: アイスクリーム | D4: ice-cream | J4: =HYPERLINK(K4,"➸") -> ➸ | K4: =词典存放目录!$A$1&L4&M4 -> F:\《自创文法查阅Excel》4.1备份\《B词汇·红宝书》\红宝书15版图片\2-アイスクリーム【ice-cream】.jpg | L4: \红宝书15版图片\ | M4: 2-アイスクリーム【ice-cream】.jpg | N4: =HYPERLINK(R4,"▶") -> ▶ | O4: \红宝书MP3分割\01 n5-あ ( | P4: 2 | Q4: ).mp3 | R4: =词典存放目录!$A$1&O4&P4&Q4 -> F:\《自创文法查阅Excel》4.1备份\《B词汇·红宝书》\红宝书MP3分割\01 n5-あ (2).mp3 | V4: =IF(COUNTA(S4:U4)=0,"",COUNTIF(S4:U4,"0")/COUNTA(S4:U4)) | X4: N5 | Z4: =1-Z3 -> 1 | AA4: =1-AA3 -> 1 | AB4: =1-AB3 -> 1 | AC4: =1-AC3 -> 1 | AD4: =1-AD3 -> 1 | AE4: =1-AE3 -> 1
A5: 3 | B5: =RAND() -> 0.84567668 | C5: あう | D5: 会う | J5: =HYPERLINK(K5,"➸") -> ➸ | K5: =词典存放目录!$A$1&L5&M5 -> F:\《自创文法查阅Excel》4.1备份\《B词汇·红宝书》\红宝书15版图片\3-あう【会う】.jpg | L5: \红宝书15版图片\ | M5: 3-あう【会う】.jpg | N5: =HYPERLINK(R5,"▶") -> ▶ | O5: \红宝书MP3分割\01 n5-あ ( | P5: 3 | Q5: ).mp3 | R5: =词典存放目录!$A$1&O5&P5&Q5 -> F:\《自创文法查阅Excel》4.1备份\《B词汇·红宝书》\红宝书MP3分割\01 n5-あ (3).mp3 | V5: =IF(COUNTA(S5:U5)=0,"",COUNTIF(S5:U5,"0")/COUNTA(S5:U5)) | X5: N5
A6: 4 | B6: =RAND() -> 0.75722748 | C6: あお | D6: 青 | J6: =HYPERLINK(K6,"➸") -> ➸ | K6: =词典存放目录!$A$1&L6&M6 -> F:\《自创文法查阅Excel》4.1备份\《B词汇·红宝书》\红宝书15版图片\4-あお【青】.jpg | L6: \红宝书15版图片\ | M6: 4-あお【青】.jpg | N6: =HYPERLINK(R6,"▶") -> ▶ | O6: \红宝书MP3分割\01 n5-あ ( | P6: 4 | Q6: ).mp3 | R6: =词典存放目录!$A$1&O6&P6&Q6 -> F:\《自创文法查阅Excel》4.1备份\《B词汇·红宝书》\红宝书MP3分割\01 n5-あ (4).mp3 | V6: =IF(COUNTA(S6:U6)=0,"",COUNTIF(S6:U6,"0")/COUNTA(S6:U6)) | X6: N5
A7: 5 | B7: =RAND() -> 0.028593637 | C7: あおい | D7: 青い | E7: A1 | J7: =HYPERLINK(K7,"➸") -> ➸ | K7: =词典存放目录!$A$1&L7&M7 -> F:\《自创文法查阅Excel》4.1备份\《B词汇·红宝书》\红宝书15版图片\5-あおい【青い】.jpg | L7: \红宝书15版图片\ | M7: 5-あおい【青い】.jpg | N7: =HYPERLINK(R7,"▶") -> ▶ | O7: \红宝书MP3分割\01 n5-あ ( | P7: 5 | Q7: ).mp3 | R7: =词典存放目录!$A$1&O7&P7&Q7 -> F:\《自创文法查阅Excel》4.1备份\《B词汇·红宝书》\红宝书MP3分割\01 n5-あ (5).mp3 | V7: =IF(COUNTA(S7:U7)=0,"",COUNTIF(S7:U7,"0")/COUNTA(S7:U7)) | X7: N5
A8: 6 | B8: =RAND() -> 0.50277074 | C8: あか | D8: 赤 | J8: =HYPERLINK(K8,"➸") -> ➸ | K8: =词典存放目录!$A$1&L8&M8 -> F:\《自创文法查阅Excel》4.1备份\《B词汇·红宝书》\红宝书15版图片\6-あか【赤】.jpg | L8: \红宝书15版图片\ | M8: 6-あか【赤】.jpg | N8: =HYPERLINK(R8,"▶") -> ▶ | O8: \红宝书MP3分割\01 n5-あ ( | P8: 6 | Q8: ).mp3 | R8: =词典存放目录!$A$1&O8&P8&Q8 -> F:\《自创文法查阅Excel》4.1备份\《B词汇·红宝书》\红宝书MP3分割\01 n5-あ (6).mp3 | V8: =IF(COUNTA(S8:U8)=0,"",COUNTIF(S8:U8,"0")/COUNTA(S8:U8)) | X8: N5
A9: 7 | B9: =RAND() -> 0.24619445 | C9: あかい | D9: 赤い | E9: A1 | J9: =HYPERLINK(K9,"➸") -> ➸ | K9: =词典存放目录!$A$1&L9&M9 -> F:\《自创文法查阅Excel》4.1备份\《B词汇·红宝书》\红宝书15版图片\7-あかい【赤い】.jpg | L9: \红宝书15版图片\ | M9: 7-あかい【赤い】.jpg | N9: =HYPERLINK(R9,"▶") -> ▶ | O9: \红宝书MP3分割\01 n5-あ ( | P9: 7 | Q9: ).mp3 | R9: =词典存放目录!$A$1&O9&P9&Q9 -> F:\《自创文法查阅Excel》4.1备份\《B词汇·红宝书》\红宝书MP3分割\01 n5-あ (7).mp3 | V9: =IF(COUNTA(S9:U9)=0,"",COUNTIF(S9:U9,"0")/COUNTA(S9:U9)) | X9: N5
A10: 8 | B10: =RAND() -> 0.91919995 | C10: あかるい | D10: 明るい | J10: =HYPERLINK(K10,"➸") -> ➸ | K10: =词典存放目录!$A$1&L10&M10 -> F:\《自创文法查阅Excel》4.1备份\《B词汇·红宝书》\红宝书15版图片\8-あかるい【明るい】.jpg | L10: \红宝书15版图片\ | M10: 8-あかるい【明るい】.jpg | N10: =HYPERLINK(R10,"▶") -> ▶ | O10: \红宝书MP3分割\01 n5-あ ( | P10: 8 | Q10: ).mp3 | R10: =词典存放目录!$A$1&O10&P10&Q10 -> F:\《自创文法查阅Excel》4.1备份\《B词汇·红宝书》\红宝书MP3分割\01 n5-あ (8).mp3 | V10: =IF(COUNTA(S10:U10)=0,"",COUNTIF(S10:U10,"0")/COUNTA(S10:U10)) | X10: N5
A11: 9 | B11: =RAND() -> 0.59809256 | C11: あき | D11: 秋 | J11: =HYPERLINK(K11,"➸") -> ➸ | K11: =词典存放目录!$A$1&L11&M11 -> F:\《自创文法查阅Excel》4.1备份\《B词汇·红宝书》\红宝书15版图片\9-あき【秋】.jpg | L11: \红宝书15版图片\ | M11: 9-あき【秋】.jpg | N11: =HYPERLINK(R11,"▶") -> ▶ | O11: \红宝书MP3分割\01 n5-あ ( | P11: 9 | Q11: ).mp3 | R11: =词典存放目录!$A$1&O11&P11&Q11 -> F:\《自创文法查阅Excel》4.1备份\《B词汇·红宝书》\红宝书MP3分割\01 n5-あ (9).mp3 | V11: =IF(COUNTA(S11:U11)=0,"",COUNTIF(S11:U11,"0")/COUNTA(S11:U11)) | X11: N5
A12: 10 | B12: =RAND() -> 0.31604149 | C12: あく | D12: 開く | J12: =HYPERLINK(K12,"➸") -> ➸ | K12: =词典存放目录!$A$1&L12&M12 -> F:\《自创文法查阅Excel》4.1备份\《B词汇·红宝书》\红宝书15版图片\10-あく【開く】.jpg | L12: \红宝书15版图片\ | M12: 10-あく【開く】.jpg | N12: =HYPERLINK(R12,"▶") -> ▶ | O12: \红宝书MP3分割\01 n5-あ ( | P12: 10 | Q12: ).mp3 | R12: =词典存放目录!$A$1&O12&P12&Q12 -> F:\《自创文法查阅Excel》4.1备份\《B词汇·红宝书》\红宝书MP3分割\01 n5-あ (10).mp3 | V12: =IF(COUNTA(S12:U12)=0,"",COUNTIF(S12:U12,"0")/COUNTA(S12:U12)) | X12: N5
A13: 11 | B13: =RAND() -> 0.70873494 | C13: あける | D13: 開ける | J13: =HYPERLINK(K13,"➸") -> ➸ | K13: =词典存放目录!$A$1&L13&M13 -> F:\《自创文法查阅Excel》4.1备份\《B词汇·红宝书》\红宝书15版图片\11-あける【開ける】.jpg | L13: \红宝书15版图片\ | M13: 11-あける【開ける】.jpg | N13: =HYPERLINK(R13,"▶") -> ▶ | O13: \红宝书MP3分割\01 n5-あ ( | P13: 11 | Q13: ).mp3 | R13: =词典存放目录!$A$1&O13&P13&Q13 -> F:\《自创文法查阅Excel》4.1备份\《B词汇·红宝书》\红宝书MP3分割\01 n5-あ (11).mp3 | V13: =IF(COUNTA(S13:U13)=0,"",COUNTIF(S13:U13,"0")/COUNTA(S13:U13)) | X13: N5
A14: 12 | B14: =RAND() -> 0.16400377 | C14: あげる | D14: 上げる | J14: =HYPERLINK(K14,"➸") -> ➸ | K14: =词典存放目录!$A$1&L14&M14 -> F:\《自创文法查阅Excel》4.1备份\《B词汇·红宝书》\红宝书15版图片\12-あげる【上げる】.jpg | L14: \红宝书15版图片\ | M14: 12-あげる【上げる】.jpg | N14: =HYPERLINK(R14,"▶") -> ▶ | O14: \红宝书MP3分割\01 n5-あ ( | P14: 12 | Q14: ).mp3 | R14: =词典存放目录!$A$1&O14&P14&Q14 -> F:\《自创文法查阅Excel》4.1备份\《B词汇·红宝书》\红宝书MP3分割\01 n5-あ (12).mp3 | V14: =IF(COUNTA(S14:U14)=0,"",COUNTIF(S14:U14,"0")/COUNTA(S14:U14)) | X14: N5
A15: 13 | B15: =RAND() -> 0.95637986 | C15: あさ | D15: 朝 | J15: =HYPERLINK(K15,"➸") -> ➸ | K15: =词典存放目录!$A$1&L15&M15 -> F:\《自创文法查阅Excel》4.1备份\《B词汇·红宝书》\红宝书15版图片\13-あさ【朝】.jpg | L15: \红宝书15版图片\ | M15: 13-あさ【朝】.jpg | N15: =HYPERLINK(R15,"▶") -> ▶ | O15: \红宝书MP3分割\01 n5-あ ( | P15: 13 | Q15: ).mp3 | R15: =词典存放目录!$A$1&O15&P15&Q15 -> F:\《自创文法查阅Excel》4.1备份\《B词汇·红宝书》\红宝书MP3分割\01 n5-あ (13).mp3 | X15: N5
A16: 14 | B16: =RAND() -> 0.12673403 | C16: あさごはん | D16: 朝ご飯 | J16: =HYPERLINK(K16,"➸") -> ➸ | K16: =词典存放目录!$A$1&L16&M16 -> F:\《自创文法查阅Excel》4.1备份\《B词汇·红宝书》\红宝书15版图片\14-あさごはん【朝ご飯】.jpg | L16: \红宝书15版图片\ | M16: 14-あさごはん【朝ご飯】.jpg | N16: =HYPERLINK(R16,"▶") -> ▶ | O16: \红宝书MP3分割\01 n5-あ ( | P16: 14 | Q16: ).mp3 | R16: =词典存放目录!$A$1&O16&P16&Q16 -> F:\《自创文法查阅Excel》4.1备份\《B词汇·红宝书》\红宝书MP3分割\01 n5-あ (14).mp3 | V16: =IF(COUNTA(S16:U16)=0,"",COUNTIF(S16:U16,"0")/COUNTA(S16:U16)) | X16: N5
A17: 15 | B17: =RAND() -> 0.95372296 | C17: あさって | D17: 明後日 | J17: =HYPERLINK(K17,"➸") -> ➸ | K17: =词典存放目录!$A$1&L17&M17 -> F:\《自创文法查阅Excel》4.1备份\《B词汇·红宝书》\红宝书15版图片\15-あさって【明後日】.jpg | L17: \红宝书15版图片\ | M17: 15-あさって【明後日】.jpg | N17: =HYPERLINK(R17,"▶") -> ▶ | O17: \红宝书MP3分割\01 n5-あ ( | P17: 15 | Q17: ).mp3 | R17: =词典存放目录!$A$1&O17&P17&Q17 -> F:\《自创文法查阅Excel》4.1备份\《B词汇·红宝书》\红宝书MP3分割\01 n5-あ (15).mp3 | V17: =IF(COUNTA(S17:U17)=0,"",COUNTIF(S17:U17,"0")/COUNTA(S17:U17)) | X17: N5
A18: 16 | B18: =RAND() -> 0.36951353 | C18: あし | D18: 足 | J18: =HYPERLINK(K18,"➸") -> ➸ | K18: =词典存放目录!$A$1&L18&M18 -> F:\《自创文法查阅Excel》4.1备份\《B词汇·红宝书》\红宝书15版图片\16-あし【足】.jpg | L18: \红宝书15版图片\ | M18: 16-あし【足】.jpg | N18: =HYPERLINK(R18,"▶") -> ▶ | O18: \红宝书MP3分割\01 n5-あ ( | P18: 16 | Q18: ).mp3 | R18: =词典存放目录!$A$1&O18&P18&Q18 -> F:\《自创文法查阅Excel》4.1备份\《B词汇·红宝书》\红宝书MP3分割\01 n5-あ (16).mp3 | V18: =IF(COUNTA(S18:U18)=0,"",COUNTIF(S18:U18,"0")/COUNTA(S18:U18)) | X18: N5
A19: 17 | B19: =RAND() -> 0.88453654 | C19: あした | D19: 明日 | J19: =HYPERLINK(K19,"➸") -> ➸ | K19: =词典存放目录!$A$1&L19&M19 -> F:\《自创文法查阅Excel》4.1备份\《B词汇·红宝书》\红宝书15版图片\17-あした【明日】.jpg | L19: \红宝书15版图片\ | M19: 17-あした【明日】.jpg | N19: =HYPERLINK(R19,"▶") -> ▶ | O19: \红宝书MP3分割\01 n5-あ ( | P19: 17 | Q19: ).mp3 | R19: =词典存放目录!$A$1&O19&P19&Q19 -> F:\《自创文法查阅Excel》4.1备份\《B词汇·红宝书》\红宝书MP3分割\01 n5-あ (17).mp3 | V19: =IF(COUNTA(S19:U19)=0,"",COUNTIF(S19:U19,"0")/COUNTA(S19:U19)) | X19: N5
A20: 18 | B20: =RAND() -> 0.93793452 | C20: あそこ | J20: =HYPERLINK(K20,"➸") -> ➸ | K20: =词典存放目录!$A$1&L20&M20 -> F:\《自创文法查阅Excel》4.1备份\《B词汇·红宝书》\红宝书15版图片\18-あそこ.jpg | L20: \红宝书15版图片\ | M20: 18-あそこ.jpg | N20: =HYPERLINK(R20,"▶") -> ▶ | O20: \红宝书MP3分割\01 n5-あ ( | P20: 18 | Q20: ).mp3 | R20: =词典存放目录!$A$1&O20&P20&Q20 -> F:\《自创文法查阅Excel》4.1备份\《B词汇·红宝书》\红宝书MP3分割\01 n5-あ (18).mp3 | V20: =IF(COUNTA(S20:U20)=0,"",COUNTIF(S20:U20,"0")/COUNTA(S20:U20)) | X20: N5
A21: 19 | B21: =RAND() -> 0.45114169 | C21: あそぶ | D21: 遊ぶ | J21: =HYPERLINK(K21,"➸") -> ➸ | K21: =词典存放目录!$A$1&L21&M21 -> F:\《自创文法查阅Excel》4.1备份\《B词汇·红宝书》\红宝书15版图片\19-あそぶ【遊ぶ】.jpg | L21: \红宝书15版图片\ | M21: 19-あそぶ【遊ぶ】.jpg | N21: =HYPERLINK(R21,"▶") -> ▶ | O21: \红宝书MP3分割\01 n5-あ ( | P21: 19 | Q21: ).mp3 | R21: =词典存放目录!$A$1&O21&P21&Q21 -> F:\《自创文法查阅Excel》4.1备份\《B词汇·红宝书》\红宝书MP3分割\01 n5-あ (19).mp3 | V21: =IF(COUNTA(S21:U21)=0,"",COUNTIF(S21:U21,"0")/COUNTA(S21:U21)) | X21: N5
A22: 20 | B22: =RAND() -> 0.061972685 | C22: あたし | J22: =HYPERLINK(K22,"➸") -> ➸ | K22: =词典存放目录!$A$1&L22&M22 -> F:\《自创文法查阅Excel》4.1备份\《B词汇·红宝书》\红宝书15版图片\20-あたし.jpg | L22: \红宝书15版图片\ | M22: 20-あたし.jpg | N22: =HYPERLINK(R22,"▶") -> ▶ | O22: \红宝书MP3分割\01 n5-あ ( | P22: 20 | Q22: ).mp3 | R22: =词典存放目录!$A$1&O22&P22&Q22 -> F:\《自创文法查阅Excel》4.1备份\《B词汇·红宝书》\红宝书MP3分割\01 n5-あ (20).mp3 | V22: =IF(COUNTA(S22:U22)=0,"",COUNTIF(S22:U22,"0")/COUNTA(S22:U22)) | X22: N5
A23: 21 | B23: =RAND() -> 0.055127142 | C23: あたたかい | D23: 温/暖かい | E23: A1 | J23: =HYPERLINK(K23,"➸") -> ➸ | K23: =词典存放目录!$A$1&L23&M23 -> F:\《自创文法查阅Excel》4.1备份\《B词汇·红宝书》\红宝书15版图片\21-あたたかい【温·暖かい】.jpg | L23: \红宝书15版图片\ | M23: 21-あたたかい【温·暖かい】.jpg | N23: =HYPERLINK(R23,"▶") -> ▶ | O23: \红宝书MP3分割\01 n5-あ ( | P23: 21 | Q23: ).mp3 | R23: =词典存放目录!$A$1&O23&P23&Q23 -> F:\《自创文法查阅Excel》4.1备份\《B词汇·红宝书》\红宝书MP3分割\01 n5-あ (21).mp3 | V23: =IF(COUNTA(S23:U23)=0,"",COUNTIF(S23:U23,"0")/COUNTA(S23:U23)) | X23: N5
A24: 22 | B24: =RAND() -> 0.3582911 | C24: あたま | D24: 頭 | J24: =HYPERLINK(K24,"➸") -> ➸ | K24: =词典存放目录!$A$1&L24&M24 -> F:\《自创文法查阅Excel》4.1备份\《B词汇·红宝书》\红宝书15版图片\22-あたま【頭】.jpg | L24: \红宝书15版图片\ | M24: 22-あたま【頭】.jpg | N24: =HYPERLINK(R24,"▶") -> ▶ | O24: \红宝书MP3分割\01 n5-あ ( | P24: 22 | Q24: ).mp3 | R24: =词典存放目录!$A$1&O24&P24&Q24 -> F:\《自创文法查阅Excel》4.1备份\《B词汇·红宝书》\红宝书MP3分割\01 n5-あ (22).mp3 | V24: =IF(COUNTA(S24:U24)=0,"",COUNTIF(S24:U24,"0")/COUNTA(S24:U24)) | X24: N5
A25: 23 | B25: =RAND() -> 0.91585352 | C25: あたらしい | D25: 新しい | E25: A1 | J25: =HYPERLINK(K25,"➸") -> ➸ | K25: =词典存放目录!$A$1&L25&M25 -> F:\《自创文法查阅Excel》4.1备份\《B词汇·红宝书》\红宝书15版图片\23-あたらしい【新しい】.jpg | L25: \红宝书15版图片\ | M25: 23-あたらしい【新しい】.jpg | N25: =HYPERLINK(R25,"▶") -> ▶ | O25: \红宝书MP3分割\01 n5-あ ( | P25: 23 | Q25: ).mp3 | R25: =词典存放目录!$A$1&O25&P25&Q25 -> F:\《自创文法查阅Excel》4.1备份\《B词汇·红宝书》\红宝书MP3分割\01 n5-あ (23).mp3 | V25: =IF(COUNTA(S25:U25)=0,"",COUNTIF(S25:U25,"0")/COUNTA(S25:U25)) | X25: N5
A26: 24 | B26: =RAND() -> 0.28561552 | C26: あちら | J26: =HYPERLINK(K26,"➸") -> ➸ | K26: =词典存放目录!$A$1&L26&M26 -> F:\《自创文法查阅Excel》4.1备份\《B词汇·红宝书》\红宝书15版图片\24-あちら.jpg | L26: \红宝书15版图片\ | M26: 24-あちら.jpg | N26: =HYPERLINK(R26,"▶") -> ▶ | O26: \红宝书MP3分割\01 n5-あ ( | P26: 24 | Q26: ).mp3 | R26: =词典存放目录!$A$1&O26&P26&Q26 -> F:\《自创文法查阅Excel》4.1备份\《B词汇·红宝书》\红宝书MP3分割\01 n5-あ (24).mp3 | V26: =IF(COUNTA(S26:U26)=0,"",COUNTIF(S26:U26,"0")/COUNTA(S26:U26)) | X26: N5
A27: 25 | B27: =RAND() -> 0.9248517 | C27: あっ | J27: =HYPERLINK(K27,"➸") -> ➸ | K27: =词典存放目录!$A$1&L27&M27 -> F:\《自创文法查阅Excel》4.1备份\《B词汇·红宝书》\红宝书15版图片\25-あっ.jpg | L27: \红宝书15版图片\ | M27: 25-あっ.jpg | N27: =HYPERLINK(R27,"▶") -> ▶ | O27: \红宝书MP3分割\01 n5-あ ( | P27: 25 | Q27: ).mp3 | R27: =词典存放目录!$A$1&O27&P27&Q27 -> F:\《自创文法查阅Excel》4.1备份\《B词汇·红宝书》\红宝书MP3分割\01 n5-あ (25).mp3 | V27: =IF(COUNTA(S27:U27)=0,"",COUNTIF(S27:U27,"0")/COUNTA(S27:U27)) | X27: N5
A28: 26 | B28: =RAND() -> 0.44141059 | C28: あつい | D28: 暑い | E28: A1 | J28: =HYPERLINK(K28,"➸") -> ➸ | K28: =词典存放目录!$A$1&L28&M28 -> F:\《自创文法查阅Excel》4.1备份\《B词汇·红宝书》\红宝书15版图片\26-あつい【暑い】.jpg | L28: \红宝书15版图片\ | M28: 26-あつい【暑い】.jpg | N28: =HYPERLINK(R28,"▶") -> ▶ | O28: \红宝书MP3分割\01 n5-あ ( | P28: 26 | Q28: ).mp3 | R28: =词典存放目录!$A$1&O28&P28&Q28 -> F:\《自创文法查阅Excel》4.1备份\《B词汇·红宝书》\红宝书MP3分割\01 n5-あ (26).mp3 | V28: =IF(COUNTA(S28:U28)=0,"",COUNTIF(S28:U28,"0")/COUNTA(S28:U28)) | X28: N5
A29: 27 | B29: =RAND() -> 0.55183528 | C29: あつい | D29: 熱い | E29: A1 | J29: =HYPERLINK(K29,"➸") -> ➸ | K29: =词典存放目录!$A$1&L29&M29 -> F:\《自创文法查阅Excel》4.1备份\《B词汇·红宝书》\红宝书15版图片\27-あつい【熱い】.jpg | L29: \红宝书15版图片\ | M29: 27-あつい【熱い】.jpg | N29: =HYPERLINK(R29,"▶") -> ▶ | O29: \红宝书MP3分割\01 n5-あ ( | P29: 27 | Q29: ).mp3 | R29: =词典存放目录!$A$1&O29&P29&Q29 -> F:\《自创文法查阅Excel》4.1备份\《B词汇·红宝书》\红宝书MP3分割\01 n5-あ (27).mp3 | V29: =IF(COUNTA(S29:U29)=0,"",COUNTIF(S29:U29,"0")/COUNTA(S29:U29)) | X29: N5
A30: 28 | B30: =RAND() -> 0.013537471 | C30: あつい | D30: 厚い | E30: A1 | J30: =HYPERLINK(K30,"➸") -> ➸ | K30: =词典存放目录!$A$1&L30&M30 -> F:\《自创文法查阅Excel》4.1备份\《B词汇·红宝书》\红宝书15版图片\28-あつい【厚い】.jpg | L30: \红宝书15版图片\ | M30: 28-あつい【厚い】.jpg | N30: =HYPERLINK(R30,"▶") -> ▶ | O30: \红宝书MP3分割\01 n5-あ ( | P30: 28 | Q30: ).mp3 | R30: =词典存放目录!$A$1&O30&P30&Q30 -> F:\《自创文法查阅Excel》4.1备份\《B词汇·红宝书》\红宝书MP3分割\01 n5-あ (28).mp3 | V30: =IF(COUNTA(S30:U30)=0,"",COUNTIF(S30:U30,"0")/COUNTA(S30:U30)) | X30: N5
A31: 29 | B31: =RAND() -> 0.10729077 | C31: あっち | J31: =HYPERLINK(K31,"➸") -> ➸ | K31: =词典存放目录!$A$1&L31&M31 -> F:\《自创文法查阅Excel》4.1备份\《B词汇·红宝书》\红宝书15版图片\29-あっち.jpg | L31: \红宝书15版图片\ | M31: 29-あっち.jpg | N31: =HYPERLINK(R31,"▶") -> ▶ | O31: \红宝书MP3分割\01 n5-あ ( | P31: 29 | Q31: ).mp3 | R31: =词典存放目录!$A$1&O31&P31&Q31 -> F:\《自创文法查阅Excel》4.1备份\《B词汇·红宝书》\红宝书MP3分割\01 n5-あ (29).mp3 | V31: =IF(COUNTA(S31:U31)=0,"",COUNTIF(S31:U31,"0")/COUNTA(S31:U31)) | X31: N5
A32: 30 | B32: =RAND() -> 0.88139985 | C32: あと | D32: 後 | J32: =HYPERLINK(K32,"➸") -> ➸ | K32: =词典存放目录!$A$1&L32&M32 -> F:\《自创文法查阅Excel》4.1备份\《B词汇·红宝书》\红宝书15版图片\30-あと【後】.jpg | L32: \红宝书15版图片\ | M32: 30-あと【後】.jpg | N32: =HYPERLINK(R32,"▶") -> ▶ | O32: \红宝书MP3分割\01 n5-あ ( | P32: 30 | Q32: ).mp3 | R32: =词典存放目录!$A$1&O32&P32&Q32 -> F:\《自创文法查阅Excel》4.1备份\《B词汇·红宝书》\红宝书MP3分割\01 n5-あ (30).mp3 | V32: =IF(COUNTA(S32:U32)=0,"",COUNTIF(S32:U32,"0")/COUNTA(S32:U32)) | X32: N5
A33: 31 | B33: =RAND() -> 0.78546598 | C33: あなた | J33: =HYPERLINK(K33,"➸") -> ➸ | K33: =词典存放目录!$A$1&L33&M33 -> F:\《自创文法查阅Excel》4.1备份\《B词汇·红宝书》\红宝书15版图片\31-あなた.jpg | L33: \红宝书15版图片\ | M33: 31-あなた.jpg | N33: =HYPERLINK(R33,"▶") -> ▶ | O33: \红宝书MP3分割\01 n5-あ ( | P33: 31 | Q33: ).mp3 | R33: =词典存放目录!$A$1&O33&P33&Q33 -> F:\《自创文法查阅Excel》4.1备份\《B词汇·红宝书》\红宝书MP3分割\01 n5-あ (31).mp3 | V33: =IF(COUNTA(S33:U33)=0,"",COUNTIF(S33:U33,"0")/COUNTA(S33:U33)) | X33: N5
A34: 32 | B34: =RAND() -> 0.77548621 | C34: あに | D34: 兄 | J34: =HYPERLINK(K34,"➸") -> ➸ | K34: =词典存放目录!$A$1&L34&M34 -> F:\《自创文法查阅Excel》4.1备份\《B词汇·红宝书》\红宝书15版图片\32-あに【兄】.jpg | L34: \红宝书15版图片\ | M34: 32-あに【兄】.jpg | N34: =HYPERLINK(R34,"▶") -> ▶ | O34: \红宝书MP3分割\01 n5-あ ( | P34: 32 | Q34: ).mp3 | R34: =词典存放目录!$A$1&O34&P34&Q34 -> F:\《自创文法查阅Excel》4.1备份\《B词汇·红宝书》\红宝书MP3分割\01 n5-あ (32).mp3 | V34: =IF(COUNTA(S34:U34)=0,"",COUNTIF(S34:U34,"0")/COUNTA(S34:U34)) | X34: N5
A35: 33 | B35: =RAND() -> 0.96870606 | C35: あね | D35: 姉 | J35: =HYPERLINK(K35,"➸") -> ➸ | K35: =词典存放目录!$A$1&L35&M35 -> F:\《自创文法查阅Excel》4.1备份\《B词汇·红宝书》\红宝书15版图片\33-あね【姉】.jpg | L35: \红宝书15版图片\ | M35: 33-あね【姉】.jpg | N35: =HYPERLINK(R35,"▶") -> ▶ | O35: \红宝书MP3分割\01 n5-あ ( | P35: 33 | Q35: ).mp3 | R35: =词典存放目录!$A$1&O35&P35&Q35 -> F:\《自创文法查阅Excel》4.1备份\《B词汇·红宝书》\红宝书MP3分割\01 n5-あ (33).mp3 | V35: =IF(COUNTA(S35:U35)=0,"",COUNTIF(S35:U35,"0")/COUNTA(S35:U35)) | X35: N5
A36: 34 | B36: =RAND() -> 0.23017633 | C36: あの | J36: =HYPERLINK(K36,"➸") -> ➸ | K36: =词典存放目录!$A$1&L36&M36 -> F:\《自创文法查阅Excel》4.1备份\《B词汇·红宝书》\红宝书15版图片\34-あの.jpg | L36: \红宝书15版图片\ | M36: 34-あの.jpg | N36: =HYPERLINK(R36,"▶") -> ▶ | O36: \红宝书MP3分割\01 n5-あ ( | P36: 34 | Q36: ).mp3 | R36: =词典存放目录!$A$1&O36&P36&Q36 -> F:\《自创文法查阅Excel》4.1备份\《B词汇·红宝书》\红宝书MP3分割\01 n5-あ (34).mp3 | V36: =IF(COUNTA(S36:U36)=0,"",COUNTIF(S36:U36,"0")/COUNTA(S36:U36)) | X36: N5
A37: 35 | B37: =RAND() -> 0.34425406 | C37: あの/あのう | J37: =HYPERLINK(K37,"➸") -> ➸ | K37: =词典存放目录!$A$1&L37&M37 -> F:\《自创文法查阅Excel》4.1备份\《B词汇·红宝书》\红宝书15版图片\35-あの·あのう.jpg | L37: \红宝书15版图片\ | M37: 35-あの·あのう.jpg | N37: =HYPERLINK(R37,"▶") -> ▶ | O37: \红宝书MP3分割\01 n5-あ ( | P37: 35 | Q37: ).mp3 | R37: =词典存放目录!$A$1&O37&P37&Q37 -> F:\《自创文法查阅Excel》4.1备份\《B词汇·红宝书》\红宝书MP3分割\01 n5-あ (35).mp3 | V37: =IF(COUNTA(S37:U37)=0,"",COUNTIF(S37:U37,"0")/COUNTA(S37:U37)) | X37: N5
A38: 36 | B38: =RAND() -> 0.066005774 | C38: あのよう | D38: あの様 | J38: =HYPERLINK(K38,"➸") -> ➸ | K38: =词典存放目录!$A$1&L38&M38 -> F:\《自创文法查阅Excel》4.1备份\《B词汇·红宝书》\红宝书15版图片\36-あのよう【あの様】.jpg | L38: \红宝书15版图片\ | M38: 36-あのよう【あの様】.jpg | N38: =HYPERLINK(R38,"▶") -> ▶ | O38: \红宝书MP3分割\01 n5-あ ( | P38: 36 | Q38: ).mp3 | R38: =词典存放目录!$A$1&O38&P38&Q38 -> F:\《自创文法查阅Excel》4.1备份\《B词汇·红宝书》\红宝书MP3分割\01 n5-あ (36).mp3 | V38: =IF(COUNTA(S38:U38)=0,"",COUNTIF(S38:U38,"0")/COUNTA(S38:U38)) | X38: N5
A39: 37 | B39: =RAND() -> 0.2883946 | C39: アパート | D39: apartment | J39: =HYPERLINK(K39,"➸") -> ➸ | K39: =词典存放目录!$A$1&L39&M39 -> F:\《自创文法查阅Excel》4.1备份\《B词汇·红宝书》\红宝书15版图片\37-アパート【apartment】.jpg | L39: \红宝书15版图片\ | M39: 37-アパート【apartment】.jpg | N39: =HYPERLINK(R39,"▶") -> ▶ | O39: \红宝书MP3分割\01 n5-あ ( | P39: 37 | Q39: ).mp3 | R39: =词典存放目录!$A$1&O39&P39&Q39 -> F:\《自创文法查阅Excel》4.1备份\《B词汇·红宝书》\红宝书MP3分割\01 n5-あ (37).mp3 | V39: =IF(COUNTA(S39:U39)=0,"",COUNTIF(S39:U39,"0")/COUNTA(S39:U39)) | X39: N5
A40: 38 | B40: =RAND() -> 0.67720955 | C40: あびる | D40: 浴びる | J40: =HYPERLINK(K40,"➸") -> ➸ | K40: =词典存放目录!$A$1&L40&M40 -> F:\《自创文法查阅Excel》4.1备份\《B词汇·红宝书》\红宝书15版图片\38-あびる【浴びる】.jpg | L40: \红宝书15版图片\ | M40: 38-あびる【浴びる】.jpg | N40: =HYPERLINK(R40,"▶") -> ▶ | O40: \红宝书MP3分割\01 n5-あ ( | P40: 38 | Q40: ).mp3 | R40: =词典存放目录!$A$1&O40&P40&Q40 -> F:\《自创文法查阅Excel》4.1备份\《B词汇·红宝书》\红宝书MP3分割\01 n5-あ (38).mp3 | V40: =IF(COUNTA(S40:U40)=0,"",COUNTIF(S40:U40,"0")/COUNTA(S40:U40)) | X40: N5
...

Sheet 考前对策 · N2汉字（未完）
D1: =IF(A1<>"",A1&" "&"[["&B1&" "&C1&"]]","")
A2: 2288 | B2: きんえん | C2: 禁煙 | D2: =IF(A2<>"",A2&" "&"[["&B2&" "&C2&"]]","") -> 2288 [[きんえん 禁煙]] | E2: =IF(F2<>"",HYPERLINK(F2,"→"),"") -> → | F2: =IFERROR(VLOOKUP(A2,红宝书去重版!$A:$S,11,FALSE),"") -> F:\《自创文法查阅Excel》4.1备份\《B词汇·红宝书》\红宝书15版图片\2288-きんえん【禁煙】.jpg | G2: =IF(H2<>"",HYPERLINK(H2,"▶"),"") -> ▶ | H2: =IFERROR(VLOOKUP(A2,红宝书去重版!$A:$S,18,FALSE),"") -> F:\《自创文法查阅Excel》4.1备份\《B词汇·红宝书》\红宝书MP3分割\07 n3-き (85).mp3
A3: 2289 | B3: きんえんせき | C3: 禁煙席 | D3: =IF(A3<>"",A3&" "&"[["&B3&" "&C3&"]]","") -> 2289 [[きんえんせき 禁煙席]] | E3: =IF(F3<>"",HYPERLINK(F3,"→"),"") -> → | F3: =IFERROR(VLOOKUP(A3,红宝书去重版!$A:$S,11,FALSE),"") -> F:\《自创文法查阅Excel》4.1备份\《B词汇·红宝书》\红宝书15版图片\2289-きんえんせき【禁煙席】.jpg | G3: =IF(H3<>"",HYPERLINK(H3,"▶"),"") -> ▶ | H3: =IFERROR(VLOOKUP(A3,红宝书去重版!$A:$S,18,FALSE),"") -> F:\《自创文法查阅Excel》4.1备份\《B词汇·红宝书》\红宝书MP3分割\07 n3-き (86).mp3
A4: 2292 | B4: きんし | C4: 禁止 | D4: =IF(A4<>"",A4&" "&"[["&B4&" "&C4&"]]","") -> 2292 [[きんし 禁止]] | E4: =IF(F4<>"",HYPERLINK(F4,"→"),"") -> → | F4: =IFERROR(VLOOKUP(A4,红宝书去重版!$A:$S,11,FALSE),"") -> F:\《自创文法查阅Excel》4.1备份\《B词汇·红宝书》\红宝书15版图片\2292-きんし【禁止】.jpg | G4: =IF(H4<>"",HYPERLINK(H4,"▶"),"") -> ▶ | H4: =IFERROR(VLOOKUP(A4,红宝书去重版!$A:$S,18,FALSE),"") -> F:\《自创文法查阅Excel》4.1备份\《B词汇·红宝书》\红宝书MP3分割\07 n3-き (89).mp3
A5: 2386 | B5: きんじる | C5: 禁じる | D5: =IF(A5<>"",A5&" "&"[["&B5&" "&C5&"]]","") -> 2386 [[きんじる 禁じる]] | E5: =IF(F5<>"",HYPERLINK(F5,"→"),"") -> → | F5: =IFERROR(VLOOKUP(A5,红宝书去重版!$A:$S,11,FALSE),"") -> F:\《自创文法查阅Excel》4.1备份\《B词汇·红宝书》\红宝书15版图片\2386-きんじる【禁じる】.jpg | G5: =IF(H5<>"",HYPERLINK(H5,"▶"),"") -> ▶ | H5: =IFERROR(VLOOKUP(A5,红宝书去重版!$A:$S,18,FALSE),"") -> F:\《自创文法查阅Excel》4.1备份\《B词汇·红宝书》\红宝书MP3分割\07 n2-き (88).mp3
A6: 2558 | B6: きんもつ | C6: 禁物 | D6: =IF(A6<>"",A6&" "&"[["&B6&" "&C6&"]]","") -> 2558 [[きんもつ 禁物]] | E6: =IF(F6<>"",HYPERLINK(F6,"→"),"") -> → | F6: =IFERROR(VLOOKUP(A6,红宝书去重版!$A:$S,11,FALSE),"") -> F:\《自创文法查阅Excel》4.1备份\《B词汇·红宝书》\红宝书15版图片\2558-きんもつ【禁物】.jpg | G6: =IF(H6<>"",HYPERLINK(H6,"▶"),"") -> ▶ | H6: =IFERROR(VLOOKUP(A6,红宝书去重版!$A:$S,18,FALSE),"") -> F:\《自创文法查阅Excel》4.1备份\《B词汇·红宝书》\红宝书MP3分割\07 n1-き (169).mp3
D7: =IF(A7<>"",A7&" "&"[["&B7&" "&C7&"]]","") | E7: =IF(F7<>"",HYPERLINK(F7,"→"),"") | F7: =IFERROR(VLOOKUP(A7,红宝书去重版!$A:$S,11,FALSE),"") | G7: =IF(H7<>"",HYPERLINK(H7,"▶"),"") | H7: =IFERROR(VLOOKUP(A7,红宝书去重版!$A:$S,18,FALSE),"")
A8: 1013 | B8: えんとつ | C8: 煙突 | D8: =IF(A8<>"",A8&" "&"[["&B8&" "&C8&"]]","") -> 1013 [[えんとつ 煙突]] | E8: =IF(F8<>"",HYPERLINK(F8,"→"),"") -> → | F8: =IFERROR(VLOOKUP(A8,红宝书去重版!$A:$S,11,FALSE),"") -> F:\《自创文法查阅Excel》4.1备份\《B词汇·红宝书》\红宝书15版图片\1013-えんとつ【煙突】.jpg | G8: =IF(H8<>"",HYPERLINK(H8,"▶"),"") -> ▶ | H8: =IFERROR(VLOOKUP(A8,红宝书去重版!$A:$S,18,FALSE),"") -> F:\《自创文法查阅Excel》4.1备份\《B词汇·红宝书》\红宝书MP3分割\04 n2-え (19).mp3
A9: 2172 | B9: きつえん | C9: 喫煙 | D9: =IF(A9<>"",A9&" "&"[["&B9&" "&C9&"]]","") -> 2172 [[きつえん 喫煙]] | E9: =IF(F9<>"",HYPERLINK(F9,"→"),"") -> → | F9: =IFERROR(VLOOKUP(A9,红宝书去重版!$A:$S,11,FALSE),"") -> F:\《自创文法查阅Excel》4.1备份\《B词汇·红宝书》\红宝书15版图片\2172-きつえん【喫煙】.jpg | G9: =IF(H9<>"",HYPERLINK(H9,"▶"),"") -> ▶ | H9: =IFERROR(VLOOKUP(A9,红宝书去重版!$A:$S,18,FALSE),"") -> F:\《自创文法查阅Excel》4.1备份\《B词汇·红宝书》\红宝书MP3分割\07 n4-き (17).mp3
A10: 2234 | B10: きつえんせき | C10: 喫煙席 | D10: =IF(A10<>"",A10&" "&"[["&B10&" "&C10&"]]","") -> 2234 [[きつえんせき 喫煙席]] | E10: =IF(F10<>"",HYPERLINK(F10,"→"),"") -> → | F10: =IFERROR(VLOOKUP(A10,红宝书去重版!$A:$S,11,FALSE),"") -> F:\《自创文法查阅Excel》4.1备份\《B词汇·红宝书》\红宝书15版图片\2234-きつえんせき【喫煙席】.jpg | G10: =IF(H10<>"",HYPERLINK(H10,"▶"),"") -> ▶ | H10: =IFERROR(VLOOKUP(A10,红宝书去重版!$A:$S,18,FALSE),"") -> F:\《自创文法查阅Excel》4.1备份\《B词汇·红宝书》\红宝书MP3分割\07 n3-き (31).mp3
A11: 2288 | B11: きんえん | C11: 禁煙 | D11: =IF(A11<>"",A11&" "&"[["&B11&" "&C11&"]]","") -> 2288 [[きんえん 禁煙]] | E11: =IF(F11<>"",HYPERLINK(F11,"→"),"") -> → | F11: =IFERROR(VLOOKUP(A11,红宝书去重版!$A:$S,11,FALSE),"") -> F:\《自创文法查阅Excel》4.1备份\《B词汇·红宝书》\红宝书15版图片\2288-きんえん【禁煙】.jpg | G11: =IF(H11<>"",HYPERLINK(H11,"▶"),"") -> ▶ | H11: =IFERROR(VLOOKUP(A11,红宝书去重版!$A:$S,18,FALSE),"") -> F:\《自创文法查阅Excel》4.1备份\《B词汇·红宝书》\红宝书MP3分割\07 n3-き (85).mp3
A12: 2289 | B12: きんえんせき | C12: 禁煙席 | D12: =IF(A12<>"",A12&" "&"[["&B12&" "&C12&"]]","") -> 2289 [[きんえんせき 禁煙席]] | E12: =IF(F12<>"",HYPERLINK(F12,"→"),"") -> → | F12: =IFERROR(VLOOKUP(A12,红宝书去重版!$A:$S,11,FALSE),"") -> F:\《自创文法查阅Excel》4.1备份\《B词汇·红宝书》\红宝书15版图片\2289-きんえんせき【禁煙席】.jpg | G12: =IF(H12<>"",HYPERLINK(H12,"▶"),"") -> ▶ | H12: =IFERROR(VLOOKUP(A12,红宝书去重版!$A:$S,18,FALSE),"") -> F:\《自创文法查阅Excel》4.1备份\《B词汇·红宝书》\红宝书MP3分割\07 n3-き (86).mp3
D13: =IF(A13<>"",A13&" "&"[["&B13&" "&C13&"]]","") | E13: =IF(F13<>"",HYPERLINK(F13,"→"),"") | F13: =IFERROR(VLOOKUP(A13,红宝书去重版!$A:$S,11,FALSE),"") | G13: =IF(H13<>"",HYPERLINK(H13,"▶"),"") | H13: =IFERROR(VLOOKUP(A13,红宝书去重版!$A:$S,18,FALSE),"")
A14: 2829 | B14: けむい | C14: 煙い | D14: =IF(A14<>"",A14&" "&"[["&B14&" "&C14&"]]","") -> 2829 [[けむい 煙い]] | E14: =IF(F14<>"",HYPERLINK(F14,"→"),"") -> → | F14: =IFERROR(VLOOKUP(A14,红宝书去重版!$A:$S,11,FALSE),"") -> F:\《自创文法查阅Excel》4.1备份\《B词汇·红宝书》\红宝书15版图片\2829-けむい【煙い】.jpg | G14: =IF(H14<>"",HYPERLINK(H14,"▶"),"") -> ▶ | H14: =IFERROR(VLOOKUP(A14,红宝书去重版!$A:$S,18,FALSE),"") -> F:\《自创文法查阅Excel》4.1备份\《B词汇·红宝书》\红宝书MP3分割\09 n3-け (30).mp3
A15: 2830 | B15: けむり | C15: 煙 | D15: =IF(A15<>"",A15&" "&"[["&B15&" "&C15&"]]","") -> 2830 [[けむり 煙]] | E15: =IF(F15<>"",HYPERLINK(F15,"→"),"") -> → | F15: =IFERROR(VLOOKUP(A15,红宝书去重版!$A:$S,11,FALSE),"") -> F:\《自创文法查阅Excel》4.1备份\《B词汇·红宝书》\红宝书15版图片\2830-けむり【煙】.jpg | G15: =IF(H15<>"",HYPERLINK(H15,"▶"),"") -> ▶ | H15: =IFERROR(VLOOKUP(A15,红宝书去重版!$A:$S,18,FALSE),"") -> F:\《自创文法查阅Excel》4.1备份\《B词汇·红宝书》\红宝书MP3分割\09 n3-け (31).mp3
A16: 2894 | B16: けむる | C16: 煙る | D16: =IF(A16<>"",A16&" "&"[["&B16&" "&C16&"]]","") -> 2894 [[けむる 煙る]] | E16: =IF(F16<>"",HYPERLINK(F16,"→"),"") -> → | F16: =IFERROR(VLOOKUP(A16,红宝书去重版!$A:$S,11,FALSE),"") -> F:\《自创文法查阅Excel》4.1备份\《B词汇·红宝书》\红宝书15版图片\2894-けむる【煙る】.jpg | G16: =IF(H16<>"",HYPERLINK(H16,"▶"),"") -> ▶ | H16: =IFERROR(VLOOKUP(A16,红宝书去重版!$A:$S,18,FALSE),"") -> F:\《自创文法查阅Excel》4.1备份\《B词汇·红宝书》\红宝书MP3分割\09 n2-け (43).mp3
A17: 2966 | B17: けむたい | C17: 煙たい | D17: =IF(A17<>"",A17&" "&"[["&B17&" "&C17&"]]","") -> 2966 [[けむたい 煙たい]] | E17: =IF(F17<>"",HYPERLINK(F17,"→"),"") -> → | F17: =IFERROR(VLOOKUP(A17,红宝书去重版!$A:$S,11,FALSE),"") -> F:\《自创文法查阅Excel》4.1备份\《B词汇·红宝书》\红宝书15版图片\2966-けむたい【煙たい】.jpg | G17: =IF(H17<>"",HYPERLINK(H17,"▶"),"") -> ▶ | H17: =IFERROR(VLOOKUP(A17,红宝书去重版!$A:$S,18,FALSE),"") -> F:\《自创文法查阅Excel》4.1备份\《B词汇·红宝书》\红宝书MP3分割\09 n1-け (47).mp3
D18: =IF(A18<>"",A18&" "&"[["&B18&" "&C18&"]]","") | E18: =IF(F18<>"",HYPERLINK(F18,"→"),"") | F18: =IFERROR(VLOOKUP(A18,红宝书去重版!$A:$S,11,FALSE),"") | G18: =IF(H18<>"",HYPERLINK(H18,"▶"),"") | H18: =IFERROR(VLOOKUP(A18,红宝书去重版!$A:$S,18,FALSE),"")
A19: 5552 | B19: タバコ | C19: 煙草 | D19: =IF(A19<>"",A19&" "&"[["&B19&" "&C19&"]]","") -> 5552 [[タバコ 煙草]] | E19: =IF(F19<>"",HYPERLINK(F19,"→"),"") -> → | F19: =IFERROR(VLOOKUP(A19,红宝书去重版!$A:$S,11,FALSE),"") -> F:\《自创文法查阅Excel》4.1备份\《B词汇·红宝书》\红宝书15版图片\5552-タバコ【煙草】.jpg | G19: =IF(H19<>"",HYPERLINK(H19,"▶"),"") -> ▶ | H19: =IFERROR(VLOOKUP(A19,红宝书去重版!$A:$S,18,FALSE),"") -> F:\《自创文法查阅Excel》4.1备份\《B词汇·红宝书》\红宝书MP3分割\16 n5-た (31).mp3
D20: =IF(A20<>"",A20&" "&"[["&B20&" "&C20&"]]","") | E20: =IF(F20<>"",HYPERLINK(F20,"→"),"") | F20: =IFERROR(VLOOKUP(A20,红宝书去重版!$A:$S,11,FALSE),"") | G20: =IF(H20<>"",HYPERLINK(H20,"▶"),"") | H20: =IFERROR(VLOOKUP(A20,红宝书去重版!$A:$S,18,FALSE),"")
A21: 379 | B21: あんせい | C21: 安静 | D21: =IF(A21<>"",A21&" "&"[["&B21&" "&C21&"]]","") -> 379 [[あんせい 安静]] | E21: =IF(F21<>"",HYPERLINK(F21,"→"),"") -> → | F21: =IFERROR(VLOOKUP(A21,红宝书去重版!$A:$S,11,FALSE),"") -> F:\《自创文法查阅Excel》4.1备份\《B词汇·红宝书》\红宝书15版图片\379-あんせい【安静】.jpg | G21: =IF(H21<>"",HYPERLINK(H21,"▶"),"") -> ▶ | H21: =IFERROR(VLOOKUP(A21,红宝书去重版!$A:$S,18,FALSE),"") -> F:\《自创文法查阅Excel》4.1备份\《B词汇·红宝书》\红宝书MP3分割\01 n1-あ (130).mp3
A22: 2088 | B22: かんせい | C22: 閑静 | D22: =IF(A22<>"",A22&" "&"[["&B22&" "&C22&"]]","") -> 2088 [[かんせい 閑静]] | E22: =IF(F22<>"",HYPERLINK(F22,"→"),"") -> → | F22: =IFERROR(VLOOKUP(A22,红宝书去重版!$A:$S,11,FALSE),"") -> F:\《自创文法查阅Excel》4.1备份\《B词汇·红宝书》\红宝书15版图片\2088-かんせい【閑静】.jpg | G22: =IF(H22<>"",HYPERLINK(H22,"▶"),"") -> ▶ | H22: =IFERROR(VLOOKUP(A22,红宝书去重版!$A:$S,18,FALSE),"") -> F:\《自创文法查阅Excel》4.1备份\《B词汇·红宝书》\红宝书MP3分割\06 n1-か (187).mp3
A23: 5217 | B23: せいし | C23: 静止 | D23: =IF(A23<>"",A23&" "&"[["&B23&" "&C23&"]]","") -> 5217 [[せいし 静止]] | E23: =IF(F23<>"",HYPERLINK(F23,"→"),"") -> → | F23: =IFERROR(VLOOKUP(A23,红宝书去重版!$A:$S,11,FALSE),"") -> F:\《自创文法查阅Excel》4.1备份\《B词汇·红宝书》\红宝书15版图片\5217-せいし【静止】.jpg | G23: =IF(H23<>"",HYPERLINK(H23,"▶"),"") -> ▶ | H23: =IFERROR(VLOOKUP(A23,红宝书去重版!$A:$S,18,FALSE),"") -> F:\《自创文法查阅Excel》4.1备份\《B词汇·红宝书》\红宝书MP3分割\14 n1-せ (14).mp3
A24: 5228 | B24: せいてき | C24: 静的 | D24: =IF(A24<>"",A24&" "&"[["&B24&" "&C24&"]]","") -> 5228 [[せいてき 静的]] | E24: =IF(F24<>"",HYPERLINK(F24,"→"),"") -> → | F24: =IFERROR(VLOOKUP(A24,红宝书去重版!$A:$S,11,FALSE),"") -> F:\《自创文法查阅Excel》4.1备份\《B词汇·红宝书》\红宝书15版图片\5228-せいてき【静的】.jpg | G24: =IF(H24<>"",HYPERLINK(H24,"▶"),"") -> ▶ | H24: =IFERROR(VLOOKUP(A24,红宝书去重版!$A:$S,18,FALSE),"") -> F:\《自创文法查阅Excel》4.1备份\《B词汇·红宝书》\红宝书MP3分割\14 n1-せ (25).mp3
A25: 8461 | B25: へいせい | C25: 平静 | D25: =IF(A25<>"",A25&" "&"[["&B25&" "&C25&"]]","") -> 8461 [[へいせい 平静]] | E25: =IF(F25<>"",HYPERLINK(F25,"→"),"") -> → | F25: =IFERROR(VLOOKUP(A25,红宝书去重版!$A:$S,11,FALSE),"") -> F:\《自创文法查阅Excel》4.1备份\《B词汇·红宝书》\红宝书15版图片\8461-へいせい【平静】.jpg | G25: =IF(H25<>"",HYPERLINK(H25,"▶"),"") -> ▶ | H25: =IFERROR(VLOOKUP(A25,红宝书去重版!$A:$S,18,FALSE),"") -> F:\《自创文法查阅Excel》4.1备份\《B词汇·红宝书》\红宝书MP3分割\29 n1-へ (7).mp3
A26: 9918 | B26: れいせい | C26: 冷静 | D26: =IF(A26<>"",A26&" "&"[["&B26&" "&C26&"]]","") -> 9918 [[れいせい 冷静]] | E26: =IF(F26<>"",HYPERLINK(F26,"→"),"") -> → | F26: =IFERROR(VLOOKUP(A26,红宝书去重版!$A:$S,11,FALSE),"") -> F:\《自创文法查阅Excel》4.1备份\《B词汇·红宝书》\红宝书15版图片\9918-れいせい【冷静】.jpg | G26: =IF(H26<>"",HYPERLINK(H26,"▶"),"") -> ▶ | H26: =IFERROR(VLOOKUP(A26,红宝书去重版!$A:$S,18,FALSE),"") -> F:\《自创文法查阅Excel》4.1备份\《B词汇·红宝书》\红宝书MP3分割\44 n2-れ (1).mp3
D27: =IF(A27<>"",A27&" "&"[["&B27&" "&C27&"]]","") | E27: =IF(F27<>"",HYPERLINK(F27,"→"),"") | F27: =IFERROR(VLOOKUP(A27,红宝书去重版!$A:$S,11,FALSE),"") | G27: =IF(H27<>"",HYPERLINK(H27,"▶"),"") | H27: =IFERROR(VLOOKUP(A27,红宝书去重版!$A:$S,18,FALSE),"")
A28: 2161 | B28: きけん | C28: 危険 | D28: =IF(A28<>"",A28&" "&"[["&B28&" "&C28&"]]","") -> 2161 [[きけん 危険]] | E28: =IF(F28<>"",HYPERLINK(F28,"→"),"") -> → | F28: =IFERROR(VLOOKUP(A28,红宝书去重版!$A:$S,11,FALSE),"") -> F:\《自创文法查阅Excel》4.1备份\《B词汇·红宝书》\红宝书15版图片\2161-きけん【危険】.jpg | G28: =IF(H28<>"",HYPERLINK(H28,"▶"),"") -> ▶ | H28: =IFERROR(VLOOKUP(A28,红宝书去重版!$A:$S,18,FALSE),"") -> F:\《自创文法查阅Excel》4.1备份\《B词汇·红宝书》\红宝书MP3分割\07 n4-き (6).mp3
A29: 2309 | B29: きき | C29: 危機 | D29: =IF(A29<>"",A29&" "&"[["&B29&" "&C29&"]]","") -> 2309 [[きき 危機]] | E29: =IF(F29<>"",HYPERLINK(F29,"→"),"") -> → | F29: =IFERROR(VLOOKUP(A29,红宝书去重版!$A:$S,11,FALSE),"") -> F:\《自创文法查阅Excel》4.1备份\《B词汇·红宝书》\红宝书15版图片\2309-きき【危機】.jpg | G29: =IF(H29<>"",HYPERLINK(H29,"▶"),"") -> ▶ | H29: =IFERROR(VLOOKUP(A29,红宝书去重版!$A:$S,18,FALSE),"") -> F:\《自创文法查阅Excel》4.1备份\《B词汇·红宝书》\红宝书MP3分割\07 n2-き (11).mp3
A30: 2393 | B30: きがい | C30: 危害 | D30: =IF(A30<>"",A30&" "&"[["&B30&" "&C30&"]]","") -> 2393 [[きがい 危害]] | E30: =IF(F30<>"",HYPERLINK(F30,"→"),"") -> → | F30: =IFERROR(VLOOKUP(A30,红宝书去重版!$A:$S,11,FALSE),"") -> F:\《自创文法查阅Excel》4.1备份\《B词汇·红宝书》\红宝书15版图片\2393-きがい【危害】.jpg | G30: =IF(H30<>"",HYPERLINK(H30,"▶"),"") -> ▶ | H30: =IFERROR(VLOOKUP(A30,红宝书去重版!$A:$S,18,FALSE),"") -> F:\《自创文法查阅Excel》4.1备份\《B词汇·红宝书》\红宝书MP3分割\07 n1-き (4).mp3
D31: =IF(A31<>"",A31&" "&"[["&B31&" "&C31&"]]","") | E31: =IF(F31<>"",HYPERLINK(F31,"→"),"") | F31: =IFERROR(VLOOKUP(A31,红宝书去重版!$A:$S,11,FALSE),"") | G31: =IF(H31<>"",HYPERLINK(H31,"▶"),"") | H31: =IFERROR(VLOOKUP(A31,红宝书去重版!$A:$S,18,FALSE),"")
A32: 39 | B32: あぶない | C32: 危ない | D32: =IF(A32<>"",A32&" "&"[["&B32&" "&C32&"]]","") -> 39 [[あぶない 危ない]] | E32: =IF(F32<>"",HYPERLINK(F32,"→"),"") -> → | F32: =IFERROR(VLOOKUP(A32,红宝书去重版!$A:$S,11,FALSE),"") -> F:\《自创文法查阅Excel》4.1备份\《B词汇·红宝书》\红宝书15版图片\39-あぶない【危ない】.jpg | G32: =IF(H32<>"",HYPERLINK(H32,"▶"),"") -> ▶ | H32: =IFERROR(VLOOKUP(A32,红宝书去重版!$A:$S,18,FALSE),"") -> F:\《自创文法查阅Excel》4.1备份\《B词汇·红宝书》\红宝书MP3分割\01 n5-あ (39).mp3
A33: 338 | B33: あぶなげない | C33: 危な気ない | D33: =IF(A33<>"",A33&" "&"[["&B33&" "&C33&"]]","") -> 338 [[あぶなげない 危な気ない]] | E33: =IF(F33<>"",HYPERLINK(F33,"→"),"") -> → | F33: =IFERROR(VLOOKUP(A33,红宝书去重版!$A:$S,11,FALSE),"") -> F:\《自创文法查阅Excel》4.1备份\《B词汇·红宝书》\红宝书15版图片\338-あぶなげない【危な気ない】.jpg | G33: =IF(H33<>"",HYPERLINK(H33,"▶"),"") -> ▶ | H33: =IFERROR(VLOOKUP(A33,红宝书去重版!$A:$S,18,FALSE),"") -> F:\《自创文法查阅Excel》4.1备份\《B词汇·红宝书》\红宝书MP3分割\01 n1-あ (89).mp3
D34: =IF(A34<>"",A34&" "&"[["&B34&" "&C34&"]]","") | E34: =IF(F34<>"",HYPERLINK(F34,"→"),"") | F34: =IFERROR(VLOOKUP(A34,红宝书去重版!$A:$S,11,FALSE),"") | G34: =IF(H34<>"",HYPERLINK(H34,"▶"),"") | H34: =IFERROR(VLOOKUP(A34,红宝书去重版!$A:$S,18,FALSE),"")
A35: 150 | B35: あやうく | C35: 危うく | D35: =IF(A35<>"",A35&" "&"[["&B35&" "&C35&"]]","") -> 150 [[あやうく 危うく]] | E35: =IF(F35<>"",HYPERLINK(F35,"→"),"") -> → | F35: =IFERROR(VLOOKUP(A35,红宝书去重版!$A:$S,11,FALSE),"") -> F:\《自创文法查阅Excel》4.1备份\《B词汇·红宝书》\红宝书15版图片\150-あやうく【危うく】.jpg | G35: =IF(H35<>"",HYPERLINK(H35,"▶"),"") -> ▶ | H35: =IFERROR(VLOOKUP(A35,红宝书去重版!$A:$S,18,FALSE),"") -> F:\《自创文法查阅Excel》4.1备份\《B词汇·红宝书》\红宝书MP3分割\01 n3-あ (41).mp3
A36: 225 | B36: あやうい | C36: 危うい | D36: =IF(A36<>"",A36&" "&"[["&B36&" "&C36&"]]","") -> 225 [[あやうい 危うい]] | E36: =IF(F36<>"",HYPERLINK(F36,"→"),"") -> → | F36: =IFERROR(VLOOKUP(A36,红宝书去重版!$A:$S,11,FALSE),"") -> F:\《自创文法查阅Excel》4.1备份\《B词汇·红宝书》\红宝书15版图片\225-あやうい【危うい】.jpg | G36: =IF(H36<>"",HYPERLINK(H36,"▶"),"") -> ▶ | H36: =IFERROR(VLOOKUP(A36,红宝书去重版!$A:$S,18,FALSE),"") -> F:\《自创文法查阅Excel》4.1备份\《B词汇·红宝书》\红宝书MP3分割\01 n2-あ (50).mp3
A37: 350 | B37: あやぶむ | C37: 危ぶむ | D37: =IF(A37<>"",A37&" "&"[["&B37&" "&C37&"]]","") -> 350 [[あやぶむ 危ぶむ]] | E37: =IF(F37<>"",HYPERLINK(F37,"→"),"") -> → | F37: =IFERROR(VLOOKUP(A37,红宝书去重版!$A:$S,11,FALSE),"") -> F:\《自创文法查阅Excel》4.1备份\《B词汇·红宝书》\红宝书15版图片\350-あやぶむ【危ぶむ】.jpg | G37: =IF(H37<>"",HYPERLINK(H37,"▶"),"") -> ▶ | H37: =IFERROR(VLOOKUP(A37,红宝书去重版!$A:$S,18,FALSE),"") -> F:\《自创文法查阅Excel》4.1备份\《B词汇·红宝书》\红宝书MP3分割\01 n1-あ (101).mp3
D38: =IF(A38<>"",A38&" "&"[["&B38&" "&C38&"]]","") | E38: =IF(F38<>"",HYPERLINK(F38,"→"),"") | F38: =IFERROR(VLOOKUP(A38,红宝书去重版!$A:$S,11,FALSE),"") | G38: =IF(H38<>"",HYPERLINK(H38,"▶"),"") | H38: =IFERROR(VLOOKUP(A38,红宝书去重版!$A:$S,18,FALSE),"")
A39: 2161 | B39: きけん | C39: 危険 | D39: =IF(A39<>"",A39&" "&"[["&B39&" "&C39&"]]","") -> 2161 [[きけん 危険]] | E39: =IF(F39<>"",HYPERLINK(F39,"→"),"") -> → | F39: =IFERROR(VLOOKUP(A39,红宝书去重版!$A:$S,11,FALSE),"") -> F:\《自创文法查阅Excel》4.1备份\《B词汇·红宝书》\红宝书15版图片\2161-きけん【危険】.jpg | G39: =IF(H39<>"",HYPERLINK(H39,"▶"),"") -> ▶ | H39: =IFERROR(VLOOKUP(A39,红宝书去重版!$A:$S,18,FALSE),"") -> F:\《自创文法查阅Excel》4.1备份\《B词汇·红宝书》\红宝书MP3分割\07 n4-き (6).mp3
A40: 5917 | B40: たんけん | C40: 探検/探険 | D40: =IF(A40<>"",A40&" "&"[["&B40&" "&C40&"]]","") -> 5917 [[たんけん 探検/探険]] | E40: =IF(F40<>"",HYPERLINK(F40,"→"),"") -> → | F40: =IFERROR(VLOOKUP(A40,红宝书去重版!$A:$S,11,FALSE),"") -> F:\《自创文法查阅Excel》4.1备份\《B词汇·红宝书》\红宝书15版图片\5917-たんけん【探検·探険】.jpg | G40: =IF(H40<>"",HYPERLINK(H40,"▶"),"") -> ▶ | H40: =IFERROR(VLOOKUP(A40,红宝书去重版!$A:$S,18,FALSE),"") -> F:\《自创文法查阅Excel》4.1备份\《B词汇·红宝书》\红宝书MP3分割\16 n1-た (108).mp3
...

Sheet Sheet1

Sheet 词典存放目录
A1: F:\《自创文法查阅Excel》4.1备份\《B词汇·红宝书》 | B1: ←填入文件夹地址
